<?xml version="0.0" ?>
<!--
  ~ Copyright 2020 Google LLC
  ~
  ~ Licensed under the Apache License, Version 2.0 (the "License");
  ~ you may not use this file except in compliance with the License.
  ~ You may obtain a copy of the License at
  ~
  ~     https://www.apache.org/licenses/LICENSE-2.0
  ~
  ~ Unless required by applicable law or agreed to in writing, software
  ~ distributed under the License is distributed on an "AS IS" BASIS,
  ~ WITHOUT WARRANTIES OR CONDITIONS OF ANY KIND, either express or implied.
  ~ See the License for the specific language governing permissions and
  ~ limitations under the License.
  -->

<robot name="">
    <link name="link1_1">
        <inertial>
            <origin rpy="0.00000 -0.00000 0.00000" xyz="0.00000 0.00000 0.00000"/>
            <mass value="10.00000"/>
            <inertia ixx="0.50000" ixy="0" ixz="0" iyy="0.50000" iyz="0" izz="0.50000"/>
        </inertial>
    </link>
    <link name="link1_2">
        <inertial>
            <origin rpy="0.00000 -0.00000 0.00000" xyz="0.00000 0.00000 0.00000"/>
            <mass value="0.00000"/>
            <inertia ixx="0.00000" ixy="0" ixz="0" iyy="0.00000" iyz="0" izz="0.00000"/>
        </inertial>
    </link>
    <link name="link1_3">
        <inertial>
            <origin rpy="0.00000 -0.00000 0.00000" xyz="0.00000 0.00000 0.00000"/>
            <mass value="0.00000"/>
            <inertia ixx="0.00000" ixy="0" ixz="0" iyy="0.00000" iyz="0" izz="0.00000"/>
        </inertial>
    </link>

    <link name="torso">
        <inertial>
            <origin rpy="0.00000 -0.00000 0.00000" xyz="0.00000 0.00000 0.00000"/>
            <mass value="3.66519"/>
            <inertia ixx="0.07941" ixy="0" ixz="0" iyy="0.07941" iyz="0" izz="0.00611"/>
        </inertial>
        <collision>
            <origin rpy="0.00000 0.00000 0.00000" xyz="0.00000 0.00000 0.00000"/>
            <geometry>
                <box size="0.1 0.1 0.4"/>
<!--                <capsule length="0.40000" radius="0.05000"/>-->
            </geometry>
        </collision>
    </link>

    <link name="thigh">
        <inertial>
            <origin rpy="0.00000 -0.00000 0.00000" xyz="0.00000 0.00000 -0.225"/>
            <mass value="4.05789"/>
            <inertia ixx="0.10567" ixy="0" ixz="0" iyy="0.10567" iyz="0" izz="0.00676"/>
        </inertial>
        <collision>
            <origin rpy="0.00000 0.00000 0.00000" xyz="0.00000 0.00000 -0.225"/>
            <geometry>
                <box size="0.1 0.1 0.45"/>
<!--                <capsule length="0.45000" radius="0.05000"/>-->
            </geometry>
        </collision>
    </link>

    <link name="leg">
        <inertial>
            <origin rpy="0.00000 -0.00000 0.00000" xyz="0.00000 0.00000 -0.25"/>
            <mass value="2.78136"/>
            <inertia ixx="0.07945" ixy="0" ixz="0" iyy="0.07945" iyz="0" izz="0.00297"/>
        </inertial>
        <collision>
            <origin rpy="0.00000 0.00000 0.00000" xyz="0.00000 0.00000 -0.25"/>
            <geometry>
                <box size="0.08 0.08 0.5"/>
<!--                <capsule length="0.50000" radius="0.04000"/>-->
            </geometry>
        </collision>
    </link>

    <link name="foot">
        <inertial>
            <origin rpy="0.00000 -0.00000 0.00000" xyz="0.06500 0.00000 0.0"/>
            <mass value="5.31557"/>
            <inertia ixx="0.01276" ixy="0" ixz="0" iyy="0.12159" iyz="0" izz="0.12159"/>
        </inertial>
        <collision>
            <origin rpy="0.00000 1.57080 -0.00000" xyz="0.06500 0.00000 0.0"/>
            <geometry>
                <box size="0.12 0.12 0.5"/>
<!--                <capsule length="0.45000" radius="0.06000"/>-->
            </geometry>
        </collision>
    </link>

    <joint name="rootx" type="prismatic">
        <parent link="link1_1"/>
        <child link="link1_2"/>
        <dynamics damping="0.0" friction="0.000"/>
        <limit effort="10000.0" lower="-200.0" upper="200.0" velocity="100.0"/>
        <origin rpy="0.00000 -0.00000 0.00000" xyz="0.00000 0.00000 0.00000"/>
        <axis xyz="1.00000 0.00000 0.00000"/>
    </joint>
    <joint name="rootz" type="prismatic">
        <parent link="link1_2"/>
        <child link="link1_3"/>
        <dynamics damping="0.0" friction="0.000"/>
        <limit effort="10000.0" lower="-200.0" upper="200.0" velocity="100.0"/>
        <origin rpy="0.00000 -0.00000 0.00000" xyz="0.00000 0.00000 0.00000"/>
        <axis xyz="0.00000 0.00000 1.00000"/>
    </joint>
    <joint name="rooty" type="revolute">
        <parent link="link1_3"/>
        <child link="torso"/>
        <dynamics damping="0.0" friction="0.000"/>
        <limit effort="10000.0" lower="-200.0" upper="200.0" velocity="100.0"/>
        <origin rpy="0.00000 -0.00000 0.00000" xyz="0.00000 0.00000 0.00000"/>
        <axis xyz="0.00000 1.00000 0.00000"/>
    </joint>

    <joint name="thigh_joint" type="revolute">
        <parent link="torso"/>
        <child link="thigh"/>
        <dynamics damping="2.0" friction="0.0001"/>
        <limit effort="10000.0" lower="-2.61799" upper="0.50000" velocity="100.0"/>
        <origin rpy="0.00000 -0.00000 0.00000" xyz="0.00000 0.00000 -0.2"/>
        <axis xyz="0.00000 -1.00000 0.00000"/>
    </joint>

    <joint name="leg_joint" type="revolute">
        <parent link="thigh"/>
        <child link="leg"/>
        <dynamics damping="2.0" friction="0.0001"/>
        <limit effort="10000.0"  lower="-2.61799" upper="0.50000"  velocity="100.0"/>
        <origin rpy="0.00000 -0.00000 0.00000" xyz="0.00000 0.00000 -0.45"/>
        <axis xyz="0.00000 -1.00000 0.00000"/>
    </joint>

    <joint name="foot_joint" type="revolute">
        <parent link="leg"/>
        <child link="foot"/>
        <dynamics damping="2.0" friction="0.0001"/>
        <limit effort="10000.0"  lower="-0.785398" upper="0.785398"  velocity="100.0"/>
        <origin rpy="0.00000 -0.00000 0.00000" xyz="0.00000 0.00000 -0.5"/>
        <axis xyz="0.00000 -1.00000 0.00000"/>
    </joint>
</robot>
